Workbook

Sheet Monthly Summary
A1: Monthly Spending by Category
A2: Wells Fargo Everyday Checking (…6004) · Michael J & Carolyn Leigh B Dempsey · 4 statements, 5/27/26 – 9/24/26
A4: Category | B4: June 2026 | C4: July 2026 | D4: August 2026 | E4: September 2026 | F4: 4-Month Total | G4: Monthly Avg
A5: Statement period | B5: 5/27–6/24/26 | C5: 6/25–7/23/26 | D5: 7/24–8/25/26 | E5: 8/26–9/24/26
A6: Housing
A7: A&D Mortgage | B7: =SUMIFS('All Transactions'!$F$5:$F$436,'All Transactions'!$D$5:$D$436,$A7,'All Transactions'!$A$5:$A$436,B$4) -> 3411.1 | C7: =SUMIFS('All Transactions'!$F$5:$F$436,'All Transactions'!$D$5:$D$436,$A7,'All Transactions'!$A$5:$A$436,C$4) -> 3411.1 | D7: =SUMIFS('All Transactions'!$F$5:$F$436,'All Transactions'!$D$5:$D$436,$A7,'All Transactions'!$A$5:$A$436,D$4) -> 3411.1 | E7: =SUMIFS('All Transactions'!$F$5:$F$436,'All Transactions'!$D$5:$D$436,$A7,'All Transactions'!$A$5:$A$436,E$4) -> 3411.1 | F7: =SUM(B7:E7) -> 13644.4 | G7: =F7/4 -> 3411.1
A8: St. James Membership (Club) | B8: =SUMIFS('All Transactions'!$F$5:$F$436,'All Transactions'!$D$5:$D$436,$A8,'All Transactions'!$A$5:$A$436,B$4) -> 1591.78 | C8: =SUMIFS('All Transactions'!$F$5:$F$436,'All Transactions'!$D$5:$D$436,$A8,'All Transactions'!$A$5:$A$436,C$4) -> 1601.56 | D8: =SUMIFS('All Transactions'!$F$5:$F$436,'All Transactions'!$D$5:$D$436,$A8,'All Transactions'!$A$5:$A$436,D$4) -> 1492.11 | E8: =SUMIFS('All Transactions'!$F$5:$F$436,'All Transactions'!$D$5:$D$436,$A8,'All Transactions'!$A$5:$A$436,E$4) -> 1767 | F8: =SUM(B8:E8) -> 6452.45 | G8: =F8/4 -> 1613.1125
A9: St. James Plantation POA Dues | B9: =SUMIFS('All Transactions'!$F$5:$F$436,'All Transactions'!$D$5:$D$436,$A9,'All Transactions'!$A$5:$A$436,B$4) -> 692.95 | C9: =SUMIFS('All Transactions'!$F$5:$F$436,'All Transactions'!$D$5:$D$436,$A9,'All Transactions'!$A$5:$A$436,C$4) -> 0 | D9: =SUMIFS('All Transactions'!$F$5:$F$436,'All Transactions'!$D$5:$D$436,$A9,'All Transactions'!$A$5:$A$436,D$4) -> 0 | E9: =SUMIFS('All Transactions'!$F$5:$F$436,'All Transactions'!$D$5:$D$436,$A9,'All Transactions'!$A$5:$A$436,E$4) -> 0 | F9: =SUM(B9:E9) -> 692.95 | G9: =F9/4 -> 173.2375
A10: Total Housing | B10: =SUM(B7:B9) -> 5695.83 | C10: =SUM(C7:C9) -> 5012.66 | D10: =SUM(D7:D9) -> 4903.21 | E10: =SUM(E7:E9) -> 5178.1 | F10: =SUM(F7:F9) -> 20789.8 | G10: =F10/4 -> 5197.45
A12: Insurance
A13: Allstate Insurance | B13: =SUMIFS('All Transactions'!$F$5:$F$436,'All Transactions'!$D$5:$D$436,$A13,'All Transactions'!$A$5:$A$436,B$4) -> 360.42 | C13: =SUMIFS('All Transactions'!$F$5:$F$436,'All Transactions'!$D$5:$D$436,$A13,'All Transactions'!$A$5:$A$436,C$4) -> 360.42 | D13: =SUMIFS('All Transactions'!$F$5:$F$436,'All Transactions'!$D$5:$D$436,$A13,'All Transactions'!$A$5:$A$436,D$4) -> 475.42 | E13: =SUMIFS('All Transactions'!$F$5:$F$436,'All Transactions'!$D$5:$D$436,$A13,'All Transactions'!$A$5:$A$436,E$4) -> 354.17 | F13: =SUM(B13:E13) -> 1550.43 | G13: =F13/4 -> 387.6075
A14: Life Insurance (Lincoln National) | B14: =SUMIFS('All Transactions'!$F$5:$F$436,'All Transactions'!$D$5:$D$436,$A14,'All Transactions'!$A$5:$A$436,B$4) -> 79.21 | C14: =SUMIFS('All Transactions'!$F$5:$F$436,'All Transactions'!$D$5:$D$436,$A14,'All Transactions'!$A$5:$A$436,C$4) -> 73.61 | D14: =SUMIFS('All Transactions'!$F$5:$F$436,'All Transactions'!$D$5:$D$436,$A14,'All Transactions'!$A$5:$A$436,D$4) -> 73.61 | E14: =SUMIFS('All Transactions'!$F$5:$F$436,'All Transactions'!$D$5:$D$436,$A14,'All Transactions'!$A$5:$A$436,E$4) -> 73.61 | F14: =SUM(B14:E14) -> 300.04 | G14: =F14/4 -> 75.01
A15: Banner Life Insurance | B15: =SUMIFS('All Transactions'!$F$5:$F$436,'All Transactions'!$D$5:$D$436,$A15,'All Transactions'!$A$5:$A$436,B$4) -> 710.06 | C15: =SUMIFS('All Transactions'!$F$5:$F$436,'All Transactions'!$D$5:$D$436,$A15,'All Transactions'!$A$5:$A$436,C$4) -> 710.06 | D15: =SUMIFS('All Transactions'!$F$5:$F$436,'All Transactions'!$D$5:$D$436,$A15,'All Transactions'!$A$5:$A$436,D$4) -> 710.06 | E15: =SUMIFS('All Transactions'!$F$5:$F$436,'All Transactions'!$D$5:$D$436,$A15,'All Transactions'!$A$5:$A$436,E$4) -> 710.06 | F15: =SUM(B15:E15) -> 2840.24 | G15: =F15/4 -> 710.06
A16: Health Insurance – Blue Cross NC | B16: =SUMIFS('All Transactions'!$F$5:$F$436,'All Transactions'!$D$5:$D$436,$A16,'All Transactions'!$A$5:$A$436,B$4) -> 216.25 | C16: =SUMIFS('All Transactions'!$F$5:$F$436,'All Transactions'!$D$5:$D$436,$A16,'All Transactions'!$A$5:$A$436,C$4) -> 0 | D16: =SUMIFS('All Transactions'!$F$5:$F$436,'All Transactions'!$D$5:$D$436,$A16,'All Transactions'!$A$5:$A$436,D$4) -> 432.5 | E16: =SUMIFS('All Transactions'!$F$5:$F$436,'All Transactions'!$D$5:$D$436,$A16,'All Transactions'!$A$5:$A$436,E$4) -> 216.25 | F16: =SUM(B16:E16) -> 865 | G16: =F16/4 -> 216.25
A17: Dental Insurance – Delta Dental | B17: =SUMIFS('All Transactions'!$F$5:$F$436,'All Transactions'!$D$5:$D$436,$A17,'All Transactions'!$A$5:$A$436,B$4) -> 69.36 | C17: =SUMIFS('All Transactions'!$F$5:$F$436,'All Transactions'!$D$5:$D$436,$A17,'All Transactions'!$A$5:$A$436,C$4) -> 69.36 | D17: =SUMIFS('All Transactions'!$F$5:$F$436,'All Transactions'!$D$5:$D$436,$A17,'All Transactions'!$A$5:$A$436,D$4) -> 69.36 | E17: =SUMIFS('All Transactions'!$F$5:$F$436,'All Transactions'!$D$5:$D$436,$A17,'All Transactions'!$A$5:$A$436,E$4) -> 69.36 | F17: =SUM(B17:E17) -> 277.44 | G17: =F17/4 -> 69.36
A18: Total Insurance | B18: =SUM(B13:B17) -> 1435.3 | C18: =SUM(C13:C17) -> 1213.45 | D18: =SUM(D13:D17) -> 1760.95 | E18: =SUM(E13:E17) -> 1423.45 | F18: =SUM(F13:F17) -> 5833.15 | G18: =F18/4 -> 1458.2875
A20: Utilities
A21: Utility – Electric (BEMC) | B21: =SUMIFS('All Transactions'!$F$5:$F$436,'All Transactions'!$D$5:$D$436,$A21,'All Transactions'!$A$5:$A$436,B$4) -> 0 | C21: =SUMIFS('All Transactions'!$F$5:$F$436,'All Transactions'!$D$5:$D$436,$A21,'All Transactions'!$A$5:$A$436,C$4) -> 336.35 | D21: =SUMIFS('All Transactions'!$F$5:$F$436,'All Transactions'!$D$5:$D$436,$A21,'All Transactions'!$A$5:$A$436,D$4) -> 406.96 | E21: =SUMIFS('All Transactions'!$F$5:$F$436,'All Transactions'!$D$5:$D$436,$A21,'All Transactions'!$A$5:$A$436,E$4) -> 419.66 | F21: =SUM(B21:E21) -> 1162.97 | G21: =F21/4 -> 290.7425
A22: Utility – Water/Sewer (Brunswick County) | B22: =SUMIFS('All Transactions'!$F$5:$F$436,'All Transactions'!$D$5:$D$436,$A22,'All Transactions'!$A$5:$A$436,B$4) -> 78.84 | C22: =SUMIFS('All Transactions'!$F$5:$F$436,'All Transactions'!$D$5:$D$436,$A22,'All Transactions'!$A$5:$A$436,C$4) -> 0 | D22: =SUMIFS('All Transactions'!$F$5:$F$436,'All Transactions'!$D$5:$D$436,$A22,'All Transactions'!$A$5:$A$436,D$4) -> 179.33 | E22: =SUMIFS('All Transactions'!$F$5:$F$436,'All Transactions'!$D$5:$D$436,$A22,'All Transactions'!$A$5:$A$436,E$4) -> 84.26 | F22: =SUM(B22:E22) -> 342.43 | G22: =F22/4 -> 85.6075
A23: Total Utilities | B23: =SUM(B21:B22) -> 78.84 | C23: =SUM(C21:C22) -> 336.35 | D23: =SUM(D21:D22) -> 586.29 | E23: =SUM(E21:E22) -> 503.92 | F23: =SUM(F21:F22) -> 1505.4 | G23: =F23/4 -> 376.35
A25: Phone & Internet
A26: Internet – Focus Broadband | B26: =SUMIFS('All Transactions'!$F$5:$F$436,'All Transactions'!$D$5:$D$436,$A26,'All Transactions'!$A$5:$A$436,B$4) -> 80.79 | C26: =SUMIFS('All Transactions'!$F$5:$F$436,'All Transactions'!$D$5:$D$436,$A26,'All Transactions'!$A$5:$A$436,C$4) -> 0 | D26: =SUMIFS('All Transactions'!$F$5:$F$436,'All Transactions'!$D$5:$D$436,$A26,'All Transactions'!$A$5:$A$436,D$4) -> 161.58 | E26: =SUMIFS('All Transactions'!$F$5:$F$436,'All Transactions'!$D$5:$D$436,$A26,'All Transactions'!$A$5:$A$436,E$4) -> 80.79 | F26: =SUM(B26:E26) -> 323.16 | G26: =F26/4 -> 80.79
A27: Verizon Wireless | B27: =SUMIFS('All Transactions'!$F$5:$F$436,'All Transactions'!$D$5:$D$436,$A27,'All Transactions'!$A$5:$A$436,B$4) -> 294.57 | C27: =SUMIFS('All Transactions'!$F$5:$F$436,'All Transactions'!$D$5:$D$436,$A27,'All Transactions'!$A$5:$A$436,C$4) -> 294.8 | D27: =SUMIFS('All Transactions'!$F$5:$F$436,'All Transactions'!$D$5:$D$436,$A27,'All Transactions'!$A$5:$A$436,D$4) -> 436.02 | E27: =SUMIFS('All Transactions'!$F$5:$F$436,'All Transactions'!$D$5:$D$436,$A27,'All Transactions'!$A$5:$A$436,E$4) -> 386.85 | F27: =SUM(B27:E27) -> 1412.24 | G27: =F27/4 -> 353.06
A28: Total Phone & Internet | B28: =SUM(B26:B27) -> 375.36 | C28: =SUM(C26:C27) -> 294.8 | D28: =SUM(D26:D27) -> 597.6 | E28: =SUM(E26:E27) -> 467.64 | F28: =SUM(F26:F27) -> 1735.4 | G28: =F28/4 -> 433.85
A30: Student Loan
A31: Student Loan (Dept of Education) | B31: =SUMIFS('All Transactions'!$F$5:$F$436,'All Transactions'!$D$5:$D$436,$A31,'All Transactions'!$A$5:$A$436,B$4) -> 160.37 | C31: =SUMIFS('All Transactions'!$F$5:$F$436,'All Transactions'!$D$5:$D$436,$A31,'All Transactions'!$A$5:$A$436,C$4) -> 160.37 | D31: =SUMIFS('All Transactions'!$F$5:$F$436,'All Transactions'!$D$5:$D$436,$A31,'All Transactions'!$A$5:$A$436,D$4) -> 160.37 | E31: =SUMIFS('All Transactions'!$F$5:$F$436,'All Transactions'!$D$5:$D$436,$A31,'All Transactions'!$A$5:$A$436,E$4) -> 160.37 | F31: =SUM(B31:E31) -> 641.48 | G31: =F31/4 -> 160.37
A32: Total Student Loan | B32: =SUM(B31:B31) -> 160.37 | C32: =SUM(C31:C31) -> 160.37 | D32: =SUM(D31:D31) -> 160.37 | E32: =SUM(E31:E31) -> 160.37 | F32: =SUM(F31:F31) -> 641.48 | G32: =F32/4 -> 160.37
A34: Groceries
A35: Grocery – Lowes Foods | B35: =SUMIFS('All Transactions'!$F$5:$F$436,'All Transactions'!$D$5:$D$436,$A35,'All Transactions'!$A$5:$A$436,B$4) -> 1145.69 | C35: =SUMIFS('All Transactions'!$F$5:$F$436,'All Transactions'!$D$5:$D$436,$A35,'All Transactions'!$A$5:$A$436,C$4) -> 611.14 | D35: =SUMIFS('All Transactions'!$F$5:$F$436,'All Transactions'!$D$5:$D$436,$A35,'All Transactions'!$A$5:$A$436,D$4) -> 584.25 | E35: =SUMIFS('All Transactions'!$F$5:$F$436,'All Transactions'!$D$5:$D$436,$A35,'All Transactions'!$A$5:$A$436,E$4) -> 571.85 | F35: =SUM(B35:E35) -> 2912.93 | G35: =F35/4 -> 728.2325
A36: Grocery – Publix | B36: =SUMIFS('All Transactions'!$F$5:$F$436,'All Transactions'!$D$5:$D$436,$A36,'All Transactions'!$A$5:$A$436,B$4) -> 120.71 | C36: =SUMIFS('All Transactions'!$F$5:$F$436,'All Transactions'!$D$5:$D$436,$A36,'All Transactions'!$A$5:$A$436,C$4) -> 331.43 | D36: =SUMIFS('All Transactions'!$F$5:$F$436,'All Transactions'!$D$5:$D$436,$A36,'All Transactions'!$A$5:$A$436,D$4) -> 522.68 | E36: =SUMIFS('All Transactions'!$F$5:$F$436,'All Transactions'!$D$5:$D$436,$A36,'All Transactions'!$A$5:$A$436,E$4) -> 630.65 | F36: =SUM(B36:E36) -> 1605.47 | G36: =F36/4 -> 401.3675
A37: Grocery – Food Lion | B37: =SUMIFS('All Transactions'!$F$5:$F$436,'All Transactions'!$D$5:$D$436,$A37,'All Transactions'!$A$5:$A$436,B$4) -> 0 | C37: =SUMIFS('All Transactions'!$F$5:$F$436,'All Transactions'!$D$5:$D$436,$A37,'All Transactions'!$A$5:$A$436,C$4) -> 336.67 | D37: =SUMIFS('All Transactions'!$F$5:$F$436,'All Transactions'!$D$5:$D$436,$A37,'All Transactions'!$A$5:$A$436,D$4) -> 77.34 | E37: =SUMIFS('All Transactions'!$F$5:$F$436,'All Transactions'!$D$5:$D$436,$A37,'All Transactions'!$A$5:$A$436,E$4) -> 0 | F37: =SUM(B37:E37) -> 414.01 | G37: =F37/4 -> 103.5025
A38: Total Groceries | B38: =SUM(B35:B37) -> 1266.4 | C38: =SUM(C35:C37) -> 1279.24 | D38: =SUM(D35:D37) -> 1184.27 | E38: =SUM(E35:E37) -> 1202.5 | F38: =SUM(F35:F37) -> 4932.41 | G38: =F38/4 -> 1233.1025
A40: Food
A41: Other Food Stores (Harris Teeter, Beach Pantry) | B41: =SUMIFS('All Transactions'!$F$5:$F$436,'All Transactions'!$D$5:$D$436,$A41,'All Transactions'!$A$5:$A$436,B$4) -> 263.35 | C41: =SUMIFS('All Transactions'!$F$5:$F$436,'All Transactions'!$D$5:$D$436,$A41,'All Transactions'!$A$5:$A$436,C$4) -> 0 | D41: =SUMIFS('All Transactions'!$F$5:$F$436,'All Transactions'!$D$5:$D$436,$A41,'All Transactions'!$A$5:$A$436,D$4) -> 5.85 | E41: =SUMIFS('All Transactions'!$F$5:$F$436,'All Transactions'!$D$5:$D$436,$A41,'All Transactions'!$A$5:$A$436,E$4) -> 0 | F41: =SUM(B41:E41) -> 269.2 | G41: =F41/4 -> 67.3
A42: Restaurants & Takeout | B42: =SUMIFS('All Transactions'!$F$5:$F$436,'All Transactions'!$D$5:$D$436,$A42,'All Transactions'!$A$5:$A$436,B$4) -> 1019.45 | C42: =SUMIFS('All Transactions'!$F$5:$F$436,'All Transactions'!$D$5:$D$436,$A42,'All Transactions'!$A$5:$A$436,C$4) -> 909.94 | D42: =SUMIFS('All Transactions'!$F$5:$F$436,'All Transactions'!$D$5:$D$436,$A42,'All Transactions'!$A$5:$A$436,D$4) -> 962.62 | E42: =SUMIFS('All Transactions'!$F$5:$F$436,'All Transactions'!$D$5:$D$436,$A42,'All Transactions'!$A$5:$A$436,E$4) -> 839.3 | F42: =SUM(B42:E42) -> 3731.31 | G42: =F42/4 -> 932.8275
A43: Total Food | B43: =SUM(B41:B42) -> 1282.8 | C43: =SUM(C41:C42) -> 909.94 | D43: =SUM(D41:D42) -> 968.47 | E43: =SUM(E41:E42) -> 839.3 | F43: =SUM(F41:F42) -> 4000.51 | G43: =F43/4 -> 1000.1275
A45: Transportation
A46: Gas & Convenience Stores | B46: =SUMIFS('All Transactions'!$F$5:$F$436,'All Transactions'!$D$5:$D$436,$A46,'All Transactions'!$A$5:$A$436,B$4) -> 108.9 | C46: =SUMIFS('All Transactions'!$F$5:$F$436,'All Transactions'!$D$5:$D$436,$A46,'All Transactions'!$A$5:$A$436,C$4) -> 277.87 | D46: =SUMIFS('All Transactions'!$F$5:$F$436,'All Transactions'!$D$5:$D$436,$A46,'All Transactions'!$A$5:$A$436,D$4) -> 167.24 | E46: =SUMIFS('All Transactions'!$F$5:$F$436,'All Transactions'!$D$5:$D$436,$A46,'All Transactions'!$A$5:$A$436,E$4) -> 238.98 | F46: =SUM(B46:E46) -> 792.99 | G46: =F46/4 -> 198.2475
A47: Tolls & Parking | B47: =SUMIFS('All Transactions'!$F$5:$F$436,'All Transactions'!$D$5:$D$436,$A47,'All Transactions'!$A$5:$A$436,B$4) -> 5.84 | C47: =SUMIFS('All Transactions'!$F$5:$F$436,'All Transactions'!$D$5:$D$436,$A47,'All Transactions'!$A$5:$A$436,C$4) -> 0 | D47: =SUMIFS('All Transactions'!$F$5:$F$436,'All Transactions'!$D$5:$D$436,$A47,'All Transactions'!$A$5:$A$436,D$4) -> 18.44 | E47: =SUMIFS('All Transactions'!$F$5:$F$436,'All Transactions'!$D$5:$D$436,$A47,'All Transactions'!$A$5:$A$436,E$4) -> 68.24 | F47: =SUM(B47:E47) -> 92.52 | G47: =F47/4 -> 23.13
A48: Total Transportation | B48: =SUM(B46:B47) -> 114.74 | C48: =SUM(C46:C47) -> 277.87 | D48: =SUM(D46:D47) -> 185.68 | E48: =SUM(E46:E47) -> 307.22 | F48: =SUM(F46:F47) -> 885.51 | G48: =F48/4 -> 221.3775
...

Sheet Monthly Detail
A1: Monthly Detail — Every Spending Transaction
A2: Grouped by month, then category (same order as the Monthly Summary). Items not counted as spending are on the "Not Counted as Spending" tab.
A4: June 2026 · statement period 5/27–6/24/26
A5: Date | B5: Description | C5: Category | D5: Amount
A6: 46189 | B6: A&D Mortgage LLC Re Payment | C6: A&D Mortgage | D6: 3411.1
C7: Subtotal – A&D Mortgage | D7: =SUM(D6:D6) -> 3411.1
A8: 46195 | B8: St James 7134 Pap | C8: St. James Membership (Club) | D8: 1591.78
C9: Subtotal – St. James Membership (Club) | D9: =SUM(D8:D8) -> 1591.78
A10: 46182 | B10: St James Plantat Assn Dues | C10: St. James Plantation POA Dues | D10: 692.95
C11: Subtotal – St. James Plantation POA Dues | D11: =SUM(D10:D10) -> 692.95
A12: 46195 | B12: Allstate *Paymn | C12: Allstate Insurance | D12: 360.42
C13: Subtotal – Allstate Insurance | D13: =SUM(D12:D12) -> 360.42
A14: 46190 | B14: +Lincoln Nationa EDI Pymnt | C14: Life Insurance (Lincoln National) | D14: 79.21
C15: Subtotal – Life Insurance (Lincoln National) | D15: =SUM(D14:D14) -> 79.21
A16: 46181 | B16: Banner Life Prem Debit 17180884647 | C16: Banner Life Insurance | D16: 710.06
C17: Subtotal – Banner Life Insurance | D17: =SUM(D16:D16) -> 710.06
A18: 46169 | B18: Aci*Blue Cross NC Durham NC | C18: Health Insurance – Blue Cross NC | D18: 216.25
C19: Subtotal – Health Insurance – Blue Cross NC | D19: =SUM(D18:D18) -> 216.25
A20: 46181 | B20: Delta Dental of Delta Dent | C20: Dental Insurance – Delta Dental | D20: 69.36
C21: Subtotal – Dental Insurance – Delta Dental | D21: =SUM(D20:D20) -> 69.36
A22: 46183 | B22: Opc*Brunswick CO U | C22: Utility – Water/Sewer (Brunswick County) | D22: 75.89
A23: 46183 | B23: Opc Utl*Service Fe | C23: Utility – Water/Sewer (Brunswick County) | D23: 2.95
C24: Subtotal – Utility – Water/Sewer (Brunswick County) | D24: =SUM(D22:D23) -> 78.84
A25: 46182 | B25: Focus Broadband Clover.Com NC | C25: Internet – Focus Broadband | D25: 80.79
C26: Subtotal – Internet – Focus Broadband | D26: =SUM(D25:D25) -> 80.79
A27: 46195 | B27: Verizon Wireless Payments | C27: Verizon Wireless | D27: 294.57
C28: Subtotal – Verizon Wireless | D28: =SUM(D27:D27) -> 294.57
A29: 46188 | B29: Dept Education Student Ln 0000 | C29: Student Loan (Dept of Education) | D29: 160.37
C30: Subtotal – Student Loan (Dept of Education) | D30: =SUM(D29:D29) -> 160.37
A31: 46171 | B31: Lowes Food #235 Bolivia NC | C31: Grocery – Lowes Foods | D31: 125.08
A32: 46174 | B32: Lowes Foods #27 Southport NC | C32: Grocery – Lowes Foods | D32: 37.15
A33: 46177 | B33: Lowes Foods #27 Southport NC | C33: Grocery – Lowes Foods | D33: 225.23
A34: 46184 | B34: Lowes Food #235 Bolivia NC | C34: Grocery – Lowes Foods | D34: 53.35
A35: 46185 | B35: Lowes Foods #27 Southport NC | C35: Grocery – Lowes Foods | D35: 370.59
A36: 46189 | B36: Lowe's Foods #1 Oak Island NC | C36: Grocery – Lowes Foods | D36: 54.04
A37: 46191 | B37: Lowe's Foods #1 Oak Island NC | C37: Grocery – Lowes Foods | D37: 54.62
A38: 46195 | B38: Lowes Foods #27 Southport NC | C38: Grocery – Lowes Foods | D38: 225.63
C39: Subtotal – Grocery – Lowes Foods | D39: =SUM(D31:D38) -> 1145.69
A40: 46190 | B40: Publix #1703 Oak Island NC | C40: Grocery – Publix | D40: 120.71
C41: Subtotal – Grocery – Publix | D41: =SUM(D40:D40) -> 120.71
...

Sheet August Differences
A1: Why August Was Higher
A2: August statement (7/24–8/25/26) compared with the average of the June, July and September statements. Sorted by largest increase.
A4: Line item | B4: August | C4: Avg of Jun, Jul, Sep | D4: Difference | E4: What happened in August
A5: Retail – Walmart | B5: ='Monthly Summary'!D79 -> 1732.6 | C5: =AVERAGE('Monthly Summary'!B79,'Monthly Summary'!C79,'Monthly Summary'!E79) -> 55.096667 | D5: =B5-C5 -> 1677.5033 | E5: One large purchase of $1,461.90 on 7/31 (Southport). Aug charges: 7/31 $1,461.90; 8/10 $145.54; 8/20 $125.16
A6: Medical – Dosher Hospital (Southport) | B6: ='Monthly Summary'!D67 -> 467.66 | C6: =AVERAGE('Monthly Summary'!B67,'Monthly Summary'!C67,'Monthly Summary'!E67) -> 33.426667 | D6: =B6-C6 -> 434.23333 | E6: Aug charges: 7/29 $342.66; 8/14 $125.00
A7: CVS Pharmacy | B7: ='Monthly Summary'!D66 -> 383.24 | C7: =AVERAGE('Monthly Summary'!B66,'Monthly Summary'!C66,'Monthly Summary'!E66) -> 87 | D7: =B7-C7 -> 296.24 | E7: Aug charges: 7/31 $202.55; 8/6 $149.55; 8/19 $31.14
A8: Health Insurance – Blue Cross NC | B8: ='Monthly Summary'!D16 -> 432.5 | C8: =AVERAGE('Monthly Summary'!B16,'Monthly Summary'!C16,'Monthly Summary'!E16) -> 144.16667 | D8: =B8-C8 -> 288.33333 | E8: Two months paid in one charge; no Blue Cross payment fell in the July period. Aug charges: 7/29 $432.50
A9: Retail – Dillard's | B9: ='Monthly Summary'!D83 -> 174.74 | C9: =AVERAGE('Monthly Summary'!B83,'Monthly Summary'!C83,'Monthly Summary'!E83) -> 0 | D9: =B9-C9 -> 174.74 | E9: Aug charges: 8/14 $120.44; 8/24 $54.30
A10: Grocery – Publix | B10: ='Monthly Summary'!D36 -> 522.68 | C10: =AVERAGE('Monthly Summary'!B36,'Monthly Summary'!C36,'Monthly Summary'!E36) -> 360.93 | D10: =B10-C10 -> 161.75 | E10: Aug charges: 7/27 $85.70; 8/3 $239.44; 8/5 $15.39; 8/11 $182.15
A11: Utility – Electric (BEMC) | B11: ='Monthly Summary'!D21 -> 406.96 | C11: =AVERAGE('Monthly Summary'!B21,'Monthly Summary'!C21,'Monthly Summary'!E21) -> 252.00333 | D11: =B11-C11 -> 154.95667 | E11: No BEMC payment fell in the June period, so the other-month average is low. Aug charges: 7/29 $406.96
A12: Retail – Hobby Lobby | B12: ='Monthly Summary'!D86 -> 165.67 | C12: =AVERAGE('Monthly Summary'!B86,'Monthly Summary'!C86,'Monthly Summary'!E86) -> 12.443333 | D12: =B12-C12 -> 153.22667 | E12: Aug charges: 8/4 $20.66; 8/17 $145.01
A13: Retail – Lowe's (home improvement) | B13: ='Monthly Summary'!D87 -> 171.55 | C13: =AVERAGE('Monthly Summary'!B87,'Monthly Summary'!C87,'Monthly Summary'!E87) -> 37.646667 | D13: =B13-C13 -> 133.90333 | E13: Aug charges: 8/7 $171.55
A14: Yard Company (NextGen) | B14: ='Monthly Summary'!D98 -> 220 | C14: =AVERAGE('Monthly Summary'!B98,'Monthly Summary'!C98,'Monthly Summary'!E98) -> 93.333333 | D14: =B14-C14 -> 126.66667 | E14: Aug charges: 7/29 $100.00; 8/5 $60.00; 8/18 $60.00
A15: Utility – Water/Sewer (Brunswick County) | B15: ='Monthly Summary'!D22 -> 179.33 | C15: =AVERAGE('Monthly Summary'!B22,'Monthly Summary'!C22,'Monthly Summary'!E22) -> 54.366667 | D15: =B15-C15 -> 124.96333 | E15: Aug charges: 7/30 $91.83; 7/30 $2.95; 8/12 $81.60; 8/12 $2.95
A16: Allstate Insurance | B16: ='Monthly Summary'!D13 -> 475.42 | C16: =AVERAGE('Monthly Summary'!B13,'Monthly Summary'!C13,'Monthly Summary'!E13) -> 358.33667 | D16: =B16-C16 -> 117.08333 | E16: Extra $115 payment on 8/3 on top of the regular monthly draft. Aug charges: 8/3 $115.00; 8/20 $360.42
A17: Haircuts – The Color Bar | B17: ='Monthly Summary'!D74 -> 182.5 | C17: =AVERAGE('Monthly Summary'!B74,'Monthly Summary'!C74,'Monthly Summary'!E74) -> 71.666667 | D17: =B17-C17 -> 110.83333 | E17: Aug charges: 7/28 $32.50; 8/20 $150.00
A18: Verizon Wireless | B18: ='Monthly Summary'!D27 -> 436.02 | C18: =AVERAGE('Monthly Summary'!B27,'Monthly Summary'!C27,'Monthly Summary'!E27) -> 325.40667 | D18: =B18-C18 -> 110.61333 | E18: Higher bill than usual. Aug charges: 8/21 $436.02
A19: Internet – Focus Broadband | B19: ='Monthly Summary'!D26 -> 161.58 | C19: =AVERAGE('Monthly Summary'!B26,'Monthly Summary'!C26,'Monthly Summary'!E26) -> 53.86 | D19: =B19-C19 -> 107.72 | E19: Two monthly payments fell in this statement period. Aug charges: 7/29 $80.79; 8/10 $80.79
A20: Retail – HomeSense | B20: ='Monthly Summary'!D85 -> 88.7 | C20: =AVERAGE('Monthly Summary'!B85,'Monthly Summary'!C85,'Monthly Summary'!E85) -> 0 | D20: =B20-C20 -> 88.7 | E20: Aug charges: 8/14 $88.70
A21: Home Services (Pest Control, Lawn Treatment) | B21: ='Monthly Summary'!D99 -> 104 | C21: =AVERAGE('Monthly Summary'!B99,'Monthly Summary'!C99,'Monthly Summary'!E99) -> 47.35 | D21: =B21-C21 -> 56.65 | E21: Aug charges: 7/29 $104.00
A22: Restaurants & Takeout | B22: ='Monthly Summary'!D42 -> 962.62 | C22: =AVERAGE('Monthly Summary'!B42,'Monthly Summary'!C42,'Monthly Summary'!E42) -> 922.89667 | D22: =B22-C22 -> 39.723333 | E22: Aug charges: 7/24 $54.00; 7/27 $44.55; 7/27 $28.23; 7/27 $9.60; 7/29 $49.73
A23: Retail – Tractor Supply | B23: ='Monthly Summary'!D89 -> 29.86 | C23: =AVERAGE('Monthly Summary'!B89,'Monthly Summary'!C89,'Monthly Summary'!E89) -> 0 | D23: =B23-C23 -> 29.86 | E23: Aug charges: 8/18 $29.86
A24: Retail – Dollar Tree / Dollar General | B24: ='Monthly Summary'!D93 -> 17.35 | C24: =AVERAGE('Monthly Summary'!B93,'Monthly Summary'!C93,'Monthly Summary'!E93) -> 1.956667 | D24: =B24-C24 -> 15.393333 | E24: Aug charges: 8/4 $17.35
A25: Entertainment (Surf Cinema) | B25: ='Monthly Summary'!D108 -> 13.5 | C25: =AVERAGE('Monthly Summary'!B108,'Monthly Summary'!C108,'Monthly Summary'!E108) -> 0 | D25: =B25-C25 -> 13.5 | E25: Aug charges: 8/10 $13.50
A26: Streaming – Hulu | B26: ='Monthly Summary'!D55 -> 12.8 | C26: =AVERAGE('Monthly Summary'!B55,'Monthly Summary'!C55,'Monthly Summary'!E55) -> 4.266667 | D26: =B26-C26 -> 8.533333 | E26: Aug charges: 7/27 $12.80
A27: Transfers to People (Venmo/Zelle) | B27: ='Monthly Summary'!D112 -> 331.5 | C27: =AVERAGE('Monthly Summary'!B112,'Monthly Summary'!C112,'Monthly Summary'!E112) -> 323.01667 | D27: =B27-C27 -> 8.483333 | E27: Aug charges: 8/7 $331.50
A28: A&D Mortgage | B28: ='Monthly Summary'!D7 -> 3411.1 | C28: =AVERAGE('Monthly Summary'!B7,'Monthly Summary'!C7,'Monthly Summary'!E7) -> 3411.1 | D28: =B28-C28 -> 0 | E28: Aug charges: 8/17 $3,411.10
A29: Banner Life Insurance | B29: ='Monthly Summary'!D15 -> 710.06 | C29: =AVERAGE('Monthly Summary'!B15,'Monthly Summary'!C15,'Monthly Summary'!E15) -> 710.06 | D29: =B29-C29 -> 0 | E29: Aug charges: 8/10 $710.06
A30: Dental Insurance – Delta Dental | B30: ='Monthly Summary'!D17 -> 69.36 | C30: =AVERAGE('Monthly Summary'!B17,'Monthly Summary'!C17,'Monthly Summary'!E17) -> 69.36 | D30: =B30-C30 -> 0 | E30: Aug charges: 8/6 $69.36
A31: Student Loan (Dept of Education) | B31: ='Monthly Summary'!D31 -> 160.37 | C31: =AVERAGE('Monthly Summary'!B31,'Monthly Summary'!C31,'Monthly Summary'!E31) -> 160.37 | D31: =B31-C31 -> 0 | E31: Aug charges: 8/14 $160.37
A32: Streaming – ESPN (Sept billed as Disney Plus) | B32: ='Monthly Summary'!D52 -> 13.87 | C32: =AVERAGE('Monthly Summary'!B52,'Monthly Summary'!C52,'Monthly Summary'!E52) -> 13.87 | D32: =B32-C32 -> 0 | E32: Aug charges: 8/13 $13.87
A33: Streaming – Disney (via Roku) | B33: ='Monthly Summary'!D53 -> 20.27 | C33: =AVERAGE('Monthly Summary'!B53,'Monthly Summary'!C53,'Monthly Summary'!E53) -> 20.27 | D33: =B33-C33 -> 0 | E33: Aug charges: 7/29 $20.27
A34: Streaming – Frndly TV | B34: ='Monthly Summary'!D57 -> 22.41 | C34: =AVERAGE('Monthly Summary'!B57,'Monthly Summary'!C57,'Monthly Summary'!E57) -> 22.41 | D34: =B34-C34 -> 0 | E34: Aug charges: 8/5 $22.41
A35: Life Insurance (Lincoln National) | B35: ='Monthly Summary'!D14 -> 73.61 | C35: =AVERAGE('Monthly Summary'!B14,'Monthly Summary'!C14,'Monthly Summary'!E14) -> 75.476667 | D35: =B35-C35 -> -1.866667 | E35: Aug charges: 8/18 $73.61
A36: Medical – Duke Hospital (Durham, food & parking) | B36: ='Monthly Summary'!D70 -> 0 | C36: =AVERAGE('Monthly Summary'!B70,'Monthly Summary'!C70,'Monthly Summary'!E70) -> 4.916667 | D36: =B36-C36 -> -4.916667
A37: Tolls & Parking | B37: ='Monthly Summary'!D47 -> 18.44 | C37: =AVERAGE('Monthly Summary'!B47,'Monthly Summary'!C47,'Monthly Summary'!E47) -> 24.693333 | D37: =B37-C37 -> -6.253333 | E37: Aug charges: 7/29 $11.84; 7/31 $1.60; 7/31 $5.00
A38: Streaming – Peacock (via Roku) | B38: ='Monthly Summary'!D56 -> 0 | C38: =AVERAGE('Monthly Summary'!B56,'Monthly Summary'!C56,'Monthly Summary'!E56) -> 7.82 | D38: =B38-C38 -> -7.82
A39: Retail – Cat on a Whisk | B39: ='Monthly Summary'!D88 -> 0 | C39: =AVERAGE('Monthly Summary'!B88,'Monthly Summary'!C88,'Monthly Summary'!E88) -> 8.17 | D39: =B39-C39 -> -8.17
A40: Medical – Granville Medical Center (Oxford) | B40: ='Monthly Summary'!D69 -> 0 | C40: =AVERAGE('Monthly Summary'!B69,'Monthly Summary'!C69,'Monthly Summary'!E69) -> 8.386667 | D40: =B40-C40 -> -8.386667
A41: St. James Marina | B41: ='Monthly Summary'!D107 -> 0 | C41: =AVERAGE('Monthly Summary'!B107,'Monthly Summary'!C107,'Monthly Summary'!E107) -> 11.18 | D41: =B41-C41 -> -11.18
...

Sheet Not Counted as Spending
A1: Not Counted as Spending
A2: Withdrawals left out of the spending totals at your request. Listed here so every dollar on the bank statements is accounted for.
A4: Item | B4: June 2026 | C4: July 2026 | D4: August 2026 | E4: September 2026 | F4: 4-Month Total | G4: Monthly Avg
A5: Statement period | B5: 5/27–6/24/26 | C5: 6/25–7/23/26 | D5: 7/24–8/25/26 | E5: 8/26–9/24/26
A6: Not counted as spending
A7: WTW Health Premium (reimbursed by Via Benefits) | B7: =SUMIFS('All Transactions'!$F$5:$F$436,'All Transactions'!$D$5:$D$436,$A7,'All Transactions'!$A$5:$A$436,B$4) -> 2576 | C7: =SUMIFS('All Transactions'!$F$5:$F$436,'All Transactions'!$D$5:$D$436,$A7,'All Transactions'!$A$5:$A$436,C$4) -> 2576 | D7: =SUMIFS('All Transactions'!$F$5:$F$436,'All Transactions'!$D$5:$D$436,$A7,'All Transactions'!$A$5:$A$436,D$4) -> 2576 | E7: =SUMIFS('All Transactions'!$F$5:$F$436,'All Transactions'!$D$5:$D$436,$A7,'All Transactions'!$A$5:$A$436,E$4) -> 2576 | F7: =SUM(B7:E7) -> 10304 | G7: =F7/4 -> 2576
A8: Credit Card Payoff – American Express | B8: =SUMIFS('All Transactions'!$F$5:$F$436,'All Transactions'!$D$5:$D$436,$A8,'All Transactions'!$A$5:$A$436,B$4) -> 0 | C8: =SUMIFS('All Transactions'!$F$5:$F$436,'All Transactions'!$D$5:$D$436,$A8,'All Transactions'!$A$5:$A$436,C$4) -> 7227.09 | D8: =SUMIFS('All Transactions'!$F$5:$F$436,'All Transactions'!$D$5:$D$436,$A8,'All Transactions'!$A$5:$A$436,D$4) -> 4593.08 | E8: =SUMIFS('All Transactions'!$F$5:$F$436,'All Transactions'!$D$5:$D$436,$A8,'All Transactions'!$A$5:$A$436,E$4) -> 4738.51 | F8: =SUM(B8:E8) -> 16558.68 | G8: =F8/4 -> 4139.67
A9: Sloane Realty | B9: =SUMIFS('All Transactions'!$F$5:$F$436,'All Transactions'!$D$5:$D$436,$A9,'All Transactions'!$A$5:$A$436,B$4) -> 0 | C9: =SUMIFS('All Transactions'!$F$5:$F$436,'All Transactions'!$D$5:$D$436,$A9,'All Transactions'!$A$5:$A$436,C$4) -> 2891.98 | D9: =SUMIFS('All Transactions'!$F$5:$F$436,'All Transactions'!$D$5:$D$436,$A9,'All Transactions'!$A$5:$A$436,D$4) -> 0 | E9: =SUMIFS('All Transactions'!$F$5:$F$436,'All Transactions'!$D$5:$D$436,$A9,'All Transactions'!$A$5:$A$436,E$4) -> 0 | F9: =SUM(B9:E9) -> 2891.98 | G9: =F9/4 -> 722.995
A10: Dust and Mop House | B10: =SUMIFS('All Transactions'!$F$5:$F$436,'All Transactions'!$D$5:$D$436,$A10,'All Transactions'!$A$5:$A$436,B$4) -> 0 | C10: =SUMIFS('All Transactions'!$F$5:$F$436,'All Transactions'!$D$5:$D$436,$A10,'All Transactions'!$A$5:$A$436,C$4) -> 100 | D10: =SUMIFS('All Transactions'!$F$5:$F$436,'All Transactions'!$D$5:$D$436,$A10,'All Transactions'!$A$5:$A$436,D$4) -> 432.6 | E10: =SUMIFS('All Transactions'!$F$5:$F$436,'All Transactions'!$D$5:$D$436,$A10,'All Transactions'!$A$5:$A$436,E$4) -> 0 | F10: =SUM(B10:E10) -> 532.6 | G10: =F10/4 -> 133.15
A11: Bowery West | B11: =SUMIFS('All Transactions'!$F$5:$F$436,'All Transactions'!$D$5:$D$436,$A11,'All Transactions'!$A$5:$A$436,B$4) -> 0 | C11: =SUMIFS('All Transactions'!$F$5:$F$436,'All Transactions'!$D$5:$D$436,$A11,'All Transactions'!$A$5:$A$436,C$4) -> 400 | D11: =SUMIFS('All Transactions'!$F$5:$F$436,'All Transactions'!$D$5:$D$436,$A11,'All Transactions'!$A$5:$A$436,D$4) -> 0 | E11: =SUMIFS('All Transactions'!$F$5:$F$436,'All Transactions'!$D$5:$D$436,$A11,'All Transactions'!$A$5:$A$436,E$4) -> 0 | F11: =SUM(B11:E11) -> 400 | G11: =F11/4 -> 100
A12: Checks Written (payee not shown) | B12: =SUMIFS('All Transactions'!$F$5:$F$436,'All Transactions'!$D$5:$D$436,$A12,'All Transactions'!$A$5:$A$436,B$4) -> 2630 | C12: =SUMIFS('All Transactions'!$F$5:$F$436,'All Transactions'!$D$5:$D$436,$A12,'All Transactions'!$A$5:$A$436,C$4) -> 0 | D12: =SUMIFS('All Transactions'!$F$5:$F$436,'All Transactions'!$D$5:$D$436,$A12,'All Transactions'!$A$5:$A$436,D$4) -> 728 | E12: =SUMIFS('All Transactions'!$F$5:$F$436,'All Transactions'!$D$5:$D$436,$A12,'All Transactions'!$A$5:$A$436,E$4) -> 0 | F12: =SUM(B12:E12) -> 3358 | G12: =F12/4 -> 839.5
A13: Transfer to Own WF Account | B13: =SUMIFS('All Transactions'!$F$5:$F$436,'All Transactions'!$D$5:$D$436,$A13,'All Transactions'!$A$5:$A$436,B$4) -> 0 | C13: =SUMIFS('All Transactions'!$F$5:$F$436,'All Transactions'!$D$5:$D$436,$A13,'All Transactions'!$A$5:$A$436,C$4) -> 3.26 | D13: =SUMIFS('All Transactions'!$F$5:$F$436,'All Transactions'!$D$5:$D$436,$A13,'All Transactions'!$A$5:$A$436,D$4) -> 0 | E13: =SUMIFS('All Transactions'!$F$5:$F$436,'All Transactions'!$D$5:$D$436,$A13,'All Transactions'!$A$5:$A$436,E$4) -> 0 | F13: =SUM(B13:E13) -> 3.26 | G13: =F13/4 -> 0.815
A14: Total not counted as spending | B14: =SUM(B7:B13) -> 5206 | C14: =SUM(C7:C13) -> 13198.33 | D14: =SUM(D7:D13) -> 8329.68 | E14: =SUM(E7:E13) -> 7314.51 | F14: =SUM(F7:F13) -> 34048.52 | G14: =F14/4 -> 8512.13
A16: Reconciliation to bank statements
A17: Total spending (from Monthly Summary) | B17: ='Monthly Summary'!B120 -> 12135.81 | C17: ='Monthly Summary'!C120 -> 12163.24 | D17: ='Monthly Summary'!D120 -> 14654.04 | E17: ='Monthly Summary'!E120 -> 11515.63 | F17: ='Monthly Summary'!F120 -> 50468.72
A18: Plus: not counted as spending | B18: =B14 -> 5206 | C18: =C14 -> 13198.33 | D18: =D14 -> 8329.68 | E18: =E14 -> 7314.51 | F18: =F14 -> 34048.52
A19: Total withdrawals | B19: =B17+B18 -> 17341.81 | C19: =C17+C18 -> 25361.57 | D19: =D17+D18 -> 22983.72 | E19: =E17+E18 -> 18830.14 | F19: =F17+F18 -> 84517.24
A20: Withdrawals/Subtractions per bank statement | B20: 17341.81 | C20: 25361.57 | D20: 22983.72 | E20: 18830.14 | F20: =SUM(B20:E20) -> 84517.24
A21: Difference (should be $0) | B21: =B19-B20 -> 0 | C21: =C19-C20 -> 0 | D21: =D19-D20 -> 0 | E21: =E19-E20 -> 0 | F21: =F19-F20 -> 0
A24: Every excluded transaction
A25: Description | B25: Date | C25: Month | D25: Amount
A26: Bowery West: Rps*Bowery West CD | B26: 46224 | C26: July 2026 | D26: 75
A27: Bowery West: Rps*Bowery West CD | B27: 46224 | C27: July 2026 | D27: 125
A28: Bowery West: Rps*Bowery West CD | B28: 46224 | C28: July 2026 | D28: 75
A29: Bowery West: Rps*Bowery West CD | B29: 46224 | C29: July 2026 | D29: 125
A30: Checks Written (payee not shown): Check #520 | B30: 46174 | C30: June 2026 | D30: 1800
A31: Checks Written (payee not shown): Check #101 | B31: 46178 | C31: June 2026 | D31: 830
A32: Checks Written (payee not shown): Check #102 | B32: 46239 | C32: August 2026 | D32: 378
A33: Checks Written (payee not shown): Check #518 | B33: 46245 | C33: August 2026 | D33: 150
A34: Checks Written (payee not shown): Check #103 | B34: 46252 | C34: August 2026 | D34: 200
A35: Credit Card Payoff – American Express: American Express ACH Pmt W8716 | B35: 46199 | C35: July 2026 | D35: 226.19
A36: Credit Card Payoff – American Express: American Express ACH Pmt W8252 | B36: 46199 | C36: July 2026 | D36: 4000.9
A37: Credit Card Payoff – American Express: American Express ACH Pmt W9322 | B37: 46209 | C37: July 2026 | D37: 2000
... A49: WTW Health Premium (reimbursed by Via Benefits): Wtw Ccc Tccc 2026SEP | B49: 46274 | C49: September 2026 | D49: 2576
A50: Total | D50: =SUM(D26:D49) -> 34048.52

Sheet June 2026
A1: June 2026 Spending — statement period 5/27–6/24/26
A3: Date | B3: Description | C3: Category | D3: Group | E3: Amount | G3: Category subtotals (this month) | H3: Amount
A4: 46169 | B4: Aci*Blue Cross NC Durham NC | C4: Health Insurance – Blue Cross NC | D4: Insurance | E4: 216.25 | G4: A&D Mortgage | H4: =SUMIF($C$4:$C$119,G4,$E$4:$E$119) -> 3411.1
A5: 46169 | B5: Chipotle 4232 Conway SC | C5: Restaurants & Takeout | D5: Food | E5: 24.53 | G5: St. James Membership (Club) | H5: =SUMIF($C$4:$C$119,G5,$E$4:$E$119) -> 1591.78
A6: 46170 | B6: Chick-Fil-A #04769 Shallotte NC | C6: Restaurants & Takeout | D6: Food | E6: 11.2 | G6: Grocery – Lowes Foods | H6: =SUMIF($C$4:$C$119,G6,$E$4:$E$119) -> 1145.69
A7: 46170 | B7: Dairy Queen #15351 Supply NC | C7: Restaurants & Takeout | D7: Food | E7: 7.35 | G7: Restaurants & Takeout | H7: =SUMIF($C$4:$C$119,G7,$E$4:$E$119) -> 1019.45
A8: 46170 | B8: Belk Syf Paymnt May 28 604583156390724 Dempseyleigh | C8: Retail – Belk (store card payments) | D8: Retail | E8: 386.69 | G8: Banner Life Insurance | H8: =SUMIF($C$4:$C$119,G8,$E$4:$E$119) -> 710.06
A9: 46171 | B9: Google *Youtube Tv | C9: Streaming – YouTube TV (Google) | D9: Streaming | E9: 89 | G9: St. James Plantation POA Dues | H9: =SUMIF($C$4:$C$119,G9,$E$4:$E$119) -> 692.95
A10: 46171 | B10: Google *Youtube Tv | C10: Streaming – YouTube TV (Google) | D10: Streaming | E10: 11.78 | G10: Retail – Belk (store card payments) | H10: =SUMIF($C$4:$C$119,G10,$E$4:$E$119) -> 386.69
A11: 46171 | B11: Roku for Disney El | C11: Streaming – Disney (via Roku) | D11: Streaming | E11: 20.27 | G11: Allstate Insurance | H11: =SUMIF($C$4:$C$119,G11,$E$4:$E$119) -> 360.42
A12: 46171 | B12: Lowes Food #235 Bolivia NC | C12: Grocery – Lowes Foods | D12: Groceries | E12: 125.08 | G12: Verizon Wireless | H12: =SUMIF($C$4:$C$119,G12,$E$4:$E$119) -> 294.57
A13: 46174 | B13: Apple.Com/Bill 866-712-7753 | C13: Software & Online Subscriptions | D13: Subscriptions | E13: 13.8 | G13: Other Food Stores (Harris Teeter, Beach Pantry) | H13: =SUMIF($C$4:$C$119,G13,$E$4:$E$119) -> 263.35
A14: 46174 | B14: DD *Doordash Bella | C14: Restaurants & Takeout | D14: Food | E14: 62.84 | G14: Health Insurance – Blue Cross NC | H14: =SUMIF($C$4:$C$119,G14,$E$4:$E$119) -> 216.25
A15: 46174 | B15: Ls Mad River 186-69321801 NC | C15: Retail – Local shops (Hippie Chick, Southport Spices, Mad River, Coastal Carolina) | D15: Retail | E15: 41.63 | G15: Haircuts – The Color Bar | H15: =SUMIF($C$4:$C$119,G15,$E$4:$E$119) -> 182.5
... A40: 46181 | B40: Delta Dental of Delta Dent | C40: Dental Insurance – Delta Dental | D40: Insurance | E40: 69.36 | G40: Tolls & Parking | H40: =SUMIF($C$4:$C$119,G40,$E$4:$E$119) -> 5.84
A41: 46181 | B41: Banner Life Prem Debit 17180884647 | C41: Banner Life Insurance | D41: Insurance | E41: 710.06 | G41: Total spending | H41: =SUM(H4:H40) -> 12135.81
A42: 46182 | B42: Propertyrecs.Com | C42: Software & Online Subscriptions | D42: Subscriptions | E42: 20
A43: 46182 | B43: 365 Market H 888 4 Troy MI | C43: Restaurants & Takeout | D43: Food | E43: 5.08 | G43: Not counted as spending
A44: 46182 | B44: DD *Doordash Seasi | C44: Restaurants & Takeout | D44: Food | E44: 34.5 | G44: Checks Written (payee not shown) | H44: =SUMIF($C$4:$C$119,G44,$E$4:$E$119) -> 2630
A45: 46182 | B45: Focus Broadband Clover.Com NC | C45: Internet – Focus Broadband | D45: Phone & Internet | E45: 80.79 | G45: WTW Health Premium (reimbursed by Via Benefits) | H45: =SUMIF($C$4:$C$119,G45,$E$4:$E$119) -> 2576
A46: 46182 | B46: NC Quick Pass 877-769-7277 NC | C46: Tolls & Parking | D46: Transportation | E46: 5.84
A47: 46182 | B47: Hh 21 Winnabow NC | C47: Gas & Convenience Stores | D47: Transportation | E47: 6.39
A48: 46182 | B48: St James Plantat Assn Dues | C48: St. James Plantation POA Dues | D48: Housing | E48: 692.95
A49: 46183 | B49: Opc*Brunswick CO U | C49: Utility – Water/Sewer (Brunswick County) | D49: Utilities | E49: 75.89
A50: 46183 | B50: Opc Utl*Service Fe | C50: Utility – Water/Sewer (Brunswick County) | D50: Utilities | E50: 2.95
A51: 46183 | B51: Ross Store #2284 Shallotte NC | C51: Retail – Ross | D51: Retail | E51: 48.03
A52: 46183 | B52: Ulta 1590 Shallotte NC | C52: Retail – Ulta Beauty | D52: Retail | E52: 37.36
A53: 46183 | B53: Wawa 6129 Garner NC | C53: Gas & Convenience Stores | D53: Transportation | E53: 53.61
A54: 46184 | B54: Tst* Greek Fiesta Cary NC | C54: Restaurants & Takeout | D54: Food | E54: 36.53
A55: 46184 | B55: Cold Stone Creamer | C55: Restaurants & Takeout | D55: Food | E55: 15.14
A56: 46184 | B56: McDonald's F11779 Oxford NC | C56: Restaurants & Takeout | D56: Food | E56: 11.07
A57: 46184 | B57: Lowes Food #235 Bolivia NC | C57: Grocery – Lowes Foods | D57: Groceries | E57: 53.35
... A119: 46197 | B119: The Color Bar Hair Oak Island NC | C119: Haircuts – The Color Bar | D119: Personal | E119: 32.5
D120: Total spending | E120: =SUMIF(D4:D119,"<>Excluded",E4:E119) -> 12135.81
D121: Not counted (Excluded) | E121: =SUMIF(D4:D119,"Excluded",E4:E119) -> 5206

Sheet July 2026
A1: July 2026 Spending — statement period 6/25–7/23/26
A3: Date | B3: Description | C3: Category | D3: Group | E3: Amount | G3: Category subtotals (this month) | H3: Amount
A4: 46198 | B4: Propertyrecs.Com | C4: Software & Online Subscriptions | D4: Subscriptions | E4: 20 | G4: A&D Mortgage | H4: =SUMIF($C$4:$C$127,G4,$E$4:$E$127) -> 3411.1
A5: 46198 | B5: Jersey Mikes 3177 Southport NC | C5: Restaurants & Takeout | D5: Food | E5: 15.2 | G5: St. James Membership (Club) | H5: =SUMIF($C$4:$C$127,G5,$E$4:$E$127) -> 1601.56
A6: 46198 | B6: Apple.Com/Bill | C6: Software & Online Subscriptions | D6: Subscriptions | E6: 2.99 | G6: Retail – Belk (store card payments) | H6: =SUMIF($C$4:$C$127,G6,$E$4:$E$127) -> 948.04
A7: 46198 | B7: Shell Service Station Little River | C7: Gas & Convenience Stores | D7: Transportation | E7: 46.84 | G7: Restaurants & Takeout | H7: =SUMIF($C$4:$C$127,G7,$E$4:$E$127) -> 909.94
A8: 46198 | B8: Hulu Santa Monica CA | C8: Streaming – Hulu | D8: Streaming | E8: 12.8 | G8: Transfers to People (Venmo/Zelle) | H8: =SUMIF($C$4:$C$127,G8,$E$4:$E$127) -> 764.05
A9: 46198 | B9: Circle K # 23140 Little River SC | C9: Gas & Convenience Stores | D9: Transportation | E9: 5.78 | G9: Banner Life Insurance | H9: =SUMIF($C$4:$C$127,G9,$E$4:$E$127) -> 710.06
A10: 46198 | B10: Lowes Food #235 Bolivia NC | C10: Grocery – Lowes Foods | D10: Groceries | E10: 2.14 | G10: Grocery – Lowes Foods | H10: =SUMIF($C$4:$C$127,G10,$E$4:$E$127) -> 611.14
A11: 46199 | B11: DD *Doordash Falco | C11: Restaurants & Takeout | D11: Food | E11: 53.94 | G11: Allstate Insurance | H11: =SUMIF($C$4:$C$127,G11,$E$4:$E$127) -> 360.42
A12: 46199 | B12: DD/Br #338554 Q35 Little River | C12: Restaurants & Takeout | D12: Food | E12: 11.23 | G12: Grocery – Food Lion | H12: =SUMIF($C$4:$C$127,G12,$E$4:$E$127) -> 336.67
A13: 46199 | B13: Openai *Chatgpt Su | C13: Software & Online Subscriptions | D13: Subscriptions | E13: 20 | G13: Utility – Electric (BEMC) | H13: =SUMIF($C$4:$C$127,G13,$E$4:$E$127) -> 336.35
A14: 46199 | B14: Chipotle 2810 Myrtle Beach SC | C14: Restaurants & Takeout | D14: Food | E14: 36.74 | G14: Grocery – Publix | H14: =SUMIF($C$4:$C$127,G14,$E$4:$E$127) -> 331.43
A15: 46199 | B15: Online Transfer to Dempsey M Wells Fargo Clear Access | C15: Transfer to Own WF Account | D15: Excluded | E15: 3.26 | G15: Verizon Wireless | H15: =SUMIF($C$4:$C$127,G15,$E$4:$E$127) -> 294.8
... A35: 46204 | B35: Chick-Fil-A #0175 Henderson NC | C35: Restaurants & Takeout | D35: Food | E35: 7.37 | G35: Retail – Dollar Tree / Dollar General | H35: =SUMIF($C$4:$C$127,G35,$E$4:$E$127) -> 5.87
A36: 46204 | B36: Mms-Granville Med Oxford NC | C36: Medical – Granville Medical Center (Oxford) | D36: Health | E36: 8.85 | G36: Total spending | H36: =SUM(H4:H35) -> 12163.24
A37: 46204 | B37: Taste of China Southport NC | C37: Restaurants & Takeout | D37: Food | E37: 24.15
A38: 46204 | B38: Lil & Johnssweetre Oak Island | C38: Restaurants & Takeout | D38: Food | E38: 24.34 | G38: Not counted as spending
A39: 46204 | B39: WM Supercenter #2256 | C39: Retail – Walmart | D39: Retail | E39: 12.21 | G39: Bowery West | H39: =SUMIF($C$4:$C$127,G39,$E$4:$E$127) -> 400
A40: 46205 | B40: Chick-Fil-A #0175 Henderson NC | C40: Restaurants & Takeout | D40: Food | E40: 7.37 | G40: Credit Card Payoff – American Express | H40: =SUMIF($C$4:$C$127,G40,$E$4:$E$127) -> 7227.09
A41: 46205 | B41: Chick-Fil-A #0175 Henderson NC | C41: Restaurants & Takeout | D41: Food | E41: 10.13 | G41: Dust and Mop House | H41: =SUMIF($C$4:$C$127,G41,$E$4:$E$127) -> 100
A42: 46205 | B42: Mms-Granville Med Oxford NC | C42: Medical – Granville Medical Center (Oxford) | D42: Health | E42: 6.21 | G42: Sloane Realty | H42: =SUMIF($C$4:$C$127,G42,$E$4:$E$127) -> 2891.98
A43: 46205 | B43: Shell Service Station Henderson | C43: Gas & Convenience Stores | D43: Transportation | E43: 49.87 | G43: Transfer to Own WF Account | H43: =SUMIF($C$4:$C$127,G43,$E$4:$E$127) -> 3.26
A44: 46206 | B44: DD *Doordash Falco | C44: Restaurants & Takeout | D44: Food | E44: 50.74 | G44: WTW Health Premium (reimbursed by Via Benefits) | H44: =SUMIF($C$4:$C$127,G44,$E$4:$E$127) -> 2576
A45: 46206 | B45: Publix #1703 Oak Island NC | C45: Grocery – Publix | D45: Groceries | E45: 47.28
A46: 46209 | B46: Chick-Fil-A #0175 Henderson NC | C46: Restaurants & Takeout | D46: Food | E46: 25.88
A47: 46209 | B47: Chick-Fil-A #0175 Henderson NC | C47: Restaurants & Takeout | D47: Food | E47: 7.79
A48: 46209 | B48: Hardees 1663 Benson NC | C48: Restaurants & Takeout | D48: Food | E48: 8.53
A49: 46209 | B49: Publix #1703 Oak Island NC | C49: Grocery – Publix | D49: Groceries | E49: 94.64
A50: 46209 | B50: Frndlytv Inc*+ 1Ad | C50: Streaming – Frndly TV | D50: Streaming | E50: 22.41
A51: 46209 | B51: Venmo *Ryan | C51: Transfers to People (Venmo/Zelle) | D51: Transfers | E51: 700
A52: 46209 | B52: Sq *Saltwater Shan Supply NC | C52: Restaurants & Takeout | D52: Food | E52: 19.19
A53: 46209 | B53: Venmo *Tracy Middleton | C53: Transfers to People (Venmo/Zelle) | D53: Transfers | E53: 64.05
A54: 46209 | B54: Delta Dental of Delta Dent | C54: Dental Insurance – Delta Dental | D54: Insurance | E54: 69.36
A55: 46209 | B55: American Express ACH Pmt W9322 | C55: Credit Card Payoff – American Express | D55: Excluded | E55: 2000
A56: 46210 | B56: Autobks*Nextgen LA | C56: Yard Company (NextGen) | D56: Home | E56: 100
... A127: 46226 | B127: Dollar General # Dg 11290 | C127: Retail – Dollar Tree / Dollar General | D127: Retail | E127: 5.87
D128: Total spending | E128: =SUMIF(D4:D127,"<>Excluded",E4:E127) -> 12163.24
D129: Not counted (Excluded) | E129: =SUMIF(D4:D127,"Excluded",E4:E127) -> 13198.33

Sheet August 2026
A1: August 2026 Spending — statement period 7/24–8/25/26
A3: Date | B3: Description | C3: Category | D3: Group | E3: Amount | G3: Category subtotals (this month) | H3: Amount
A4: 46227 | B4: LA Cucina Italiano Sunset Beach | C4: Restaurants & Takeout | D4: Food | E4: 54 | G4: A&D Mortgage | H4: =SUMIF($C$4:$C$110,G4,$E$4:$E$110) -> 3411.1
A5: 46230 | B5: Blondiez Donuts Calabash NC | C5: Restaurants & Takeout | D5: Food | E5: 44.55 | G5: Retail – Walmart | H5: =SUMIF($C$4:$C$110,G5,$E$4:$E$110) -> 1732.6
A6: 46230 | B6: LA Cucina Italiano Sunset Beach | C6: Restaurants & Takeout | D6: Food | E6: 28.23 | G6: St. James Membership (Club) | H6: =SUMIF($C$4:$C$110,G6,$E$4:$E$110) -> 1492.11
A7: 46230 | B7: Apple.Com/Bill | C7: Software & Online Subscriptions | D7: Subscriptions | E7: 2.99 | G7: Restaurants & Takeout | H7: =SUMIF($C$4:$C$110,G7,$E$4:$E$110) -> 962.62
A8: 46230 | B8: Propertyrecs.Com | C8: Software & Online Subscriptions | D8: Subscriptions | E8: 20 | G8: Banner Life Insurance | H8: =SUMIF($C$4:$C$110,G8,$E$4:$E$110) -> 710.06
A9: 46230 | B9: McDonald's F35966 Supply NC | C9: Restaurants & Takeout | D9: Food | E9: 9.6 | G9: Grocery – Lowes Foods | H9: =SUMIF($C$4:$C$110,G9,$E$4:$E$110) -> 584.25
A10: 46230 | B10: Openai *Chatgpt Su | C10: Software & Online Subscriptions | D10: Subscriptions | E10: 20 | G10: Grocery – Publix | H10: =SUMIF($C$4:$C$110,G10,$E$4:$E$110) -> 522.68
A11: 46230 | B11: Hulu Santa Monica CA | C11: Streaming – Hulu | D11: Streaming | E11: 12.8 | G11: Allstate Insurance | H11: =SUMIF($C$4:$C$110,G11,$E$4:$E$110) -> 475.42
A12: 46230 | B12: Publix #1631 Ocean Isle Be NC | C12: Grocery – Publix | D12: Groceries | E12: 85.7 | G12: Medical – Dosher Hospital (Southport) | H12: =SUMIF($C$4:$C$110,G12,$E$4:$E$110) -> 467.66
A13: 46230 | B13: American Express ACH Pmt W9082 | C13: Credit Card Payoff – American Express | D13: Excluded | E13: 3929.91 | G13: Verizon Wireless | H13: =SUMIF($C$4:$C$110,G13,$E$4:$E$110) -> 436.02
A14: 46231 | B14: The Color Bar Hair Oak Island NC | C14: Haircuts – The Color Bar | D14: Personal | E14: 32.5 | G14: Health Insurance – Blue Cross NC | H14: =SUMIF($C$4:$C$110,G14,$E$4:$E$110) -> 432.5
A15: 46232 | B15: Bemc - Ecc Amanda.Wheele NC | C15: Utility – Electric (BEMC) | D15: Utilities | E15: 406.96 | G15: Utility – Electric (BEMC) | H15: =SUMIF($C$4:$C$110,G15,$E$4:$E$110) -> 406.96
... A42: 46237 | B42: Allstate *Payme 800-255-7828 | C42: Allstate Insurance | D42: Insurance | E42: 115 | G42: Other Food Stores (Harris Teeter, Beach Pantry) | H42: =SUMIF($C$4:$C$110,G42,$E$4:$E$110) -> 5.85
A43: 46237 | B43: Publix #1703 Oak Island NC | C43: Grocery – Publix | D43: Groceries | E43: 239.44 | G43: Total spending | H43: =SUM(H4:H42) -> 14654.04
A44: 46237 | B44: 7-Eleven Myrtle Beach SC | C44: Gas & Convenience Stores | D44: Transportation | E44: 9.47
A45: 46237 | B45: Circlek #2723140 3498 Little | C45: Gas & Convenience Stores | D45: Transportation | E45: 46.23 | G45: Not counted as spending
A46: 46238 | B46: DD/Br #338554 Q35 Little River | C46: Restaurants & Takeout | D46: Food | E46: 10.91 | G46: Checks Written (payee not shown) | H46: =SUMIF($C$4:$C$110,G46,$E$4:$E$110) -> 728
A47: 46238 | B47: Lowe's Foods #1 Oak Island NC | C47: Grocery – Lowes Foods | D47: Groceries | E47: 63.82 | G47: Credit Card Payoff – American Express | H47: =SUMIF($C$4:$C$110,G47,$E$4:$E$110) -> 4593.08
A48: 46238 | B48: Dollartree Southport NC | C48: Retail – Dollar Tree / Dollar General | D48: Retail | E48: 17.35 | G48: Dust and Mop House | H48: =SUMIF($C$4:$C$110,G48,$E$4:$E$110) -> 432.6
A49: 46238 | B49: Hobbylobby Southport NC | C49: Retail – Hobby Lobby | D49: Retail | E49: 20.66 | G49: WTW Health Premium (reimbursed by Via Benefits) | H49: =SUMIF($C$4:$C$110,G49,$E$4:$E$110) -> 2576
A50: 46238 | B50: Food Lion #2223 4891 L | C50: Grocery – Food Lion | D50: Groceries | E50: 77.34
A51: 46239 | B51: Del Taco 1615 Myrtle Beach SC | C51: Restaurants & Takeout | D51: Food | E51: 18.1
A52: 46239 | B52: Autobks*Nextgen LA | C52: Yard Company (NextGen) | D52: Home | E52: 60
A53: 46239 | B53: Frndlytv Inc*+ 1Ad | C53: Streaming – Frndly TV | D53: Streaming | E53: 22.41
A54: 46239 | B54: Publix #1703 Oak Island NC | C54: Grocery – Publix | D54: Groceries | E54: 15.39
A55: 46239 | B55: Dust and Mop House | C55: Dust and Mop House | D55: Excluded | E55: 432.6
A56: 46239 | B56: Check #102 | C56: Checks Written (payee not shown) | D56: Excluded | E56: 378
A57: 46240 | B57: Cvs/Pharmacy #0738 South Port | C57: CVS Pharmacy | D57: Health | E57: 149.55
A58: 46240 | B58: Lowes Foods #27 Southport NC | C58: Grocery – Lowes Foods | D58: Groceries | E58: 60.15
A59: 46240 | B59: Delta Dental of Delta Dent | C59: Dental Insurance – Delta Dental | D59: Insurance | E59: 69.36
A60: 46240 | B60: Wtw Ccc Tccc 2026Aug | C60: WTW Health Premium (reimbursed by Via Benefits) | D60: Excluded | E60: 2576
A61: 46241 | B61: Venmo *Jared Tinstman | C61: Transfers to People (Venmo/Zelle) | D61: Transfers | E61: 331.5
... A110: 46259 | B110: Apple.Com/Bill | C110: Software & Online Subscriptions | D110: Subscriptions | E110: 2.99
D111: Total spending | E111: =SUMIF(D4:D110,"<>Excluded",E4:E110) -> 14654.04
D112: Not counted (Excluded) | E112: =SUMIF(D4:D110,"Excluded",E4:E110) -> 8329.68

Sheet September 2026
A1: September 2026 Spending — statement period 8/26–9/24/26
A3: Date | B3: Description | C3: Category | D3: Group | E3: Amount | G3: Category subtotals (this month) | H3: Amount
A4: 46262 | B4: Tst*Cafe Koa - Oak Southport NC | C4: Restaurants & Takeout | D4: Food | E4: 25.81 | G4: A&D Mortgage | H4: =SUMIF($C$4:$C$88,G4,$E$4:$E$88) -> 3411.1
A5: 46262 | B5: Cat on A Whisk 9104719377 NC | C5: Retail – Cat on a Whisk | D5: Retail | E5: 24.51 | G5: St. James Membership (Club) | H5: =SUMIF($C$4:$C$88,G5,$E$4:$E$88) -> 1767
A6: 46262 | B6: Lil & Johnssweetre Oak Island | C6: Restaurants & Takeout | D6: Food | E6: 18.35 | G6: Restaurants & Takeout | H6: =SUMIF($C$4:$C$88,G6,$E$4:$E$88) -> 839.3
A7: 46265 | B7: Wilmington Eye 910-7633601 | C7: Medical – Wilmington Eye | D7: Health | E7: 60 | G7: Banner Life Insurance | H7: =SUMIF($C$4:$C$88,G7,$E$4:$E$88) -> 710.06
A8: 46265 | B8: McDonald's F7702 Southport NC | C8: Restaurants & Takeout | D8: Food | E8: 9.49 | G8: Grocery – Publix | H8: =SUMIF($C$4:$C$88,G8,$E$4:$E$88) -> 630.65
A9: 46265 | B9: Google Youtubetv | C9: Streaming – YouTube TV (Google) | D9: Streaming | E9: 89 | G9: Grocery – Lowes Foods | H9: =SUMIF($C$4:$C$88,G9,$E$4:$E$88) -> 571.85
A10: 46265 | B10: Roku for Disney El | C10: Streaming – Disney (via Roku) | D10: Streaming | E10: 20.27 | G10: Utility – Electric (BEMC) | H10: =SUMIF($C$4:$C$88,G10,$E$4:$E$88) -> 419.66
A11: 46265 | B11: Wal-Mart #2772 Southport NC | C11: Retail – Walmart | D11: Retail | E11: 32.63 | G11: Verizon Wireless | H11: =SUMIF($C$4:$C$88,G11,$E$4:$E$88) -> 386.85
A12: 46265 | B12: Burney's Bakery of Southport NC | C12: Restaurants & Takeout | D12: Food | E12: 15.17 | G12: Allstate Insurance | H12: =SUMIF($C$4:$C$88,G12,$E$4:$E$88) -> 354.17
A13: 46265 | B13: Lowes Foods #27 Southport NC | C13: Grocery – Lowes Foods | D13: Groceries | E13: 5.28 | G13: Gas & Convenience Stores | H13: =SUMIF($C$4:$C$88,G13,$E$4:$E$88) -> 238.98
A14: 46265 | B14: 365 Market H 888 4 Troy MI | C14: Restaurants & Takeout | D14: Food | E14: 8.27 | G14: Health Insurance – Blue Cross NC | H14: =SUMIF($C$4:$C$88,G14,$E$4:$E$88) -> 216.25
A15: 46265 | B15: DD *Doordash Seasi | C15: Restaurants & Takeout | D15: Food | E15: 49.01 | G15: Donations & Clubs (Kiwanis) | H15: =SUMIF($C$4:$C$88,G15,$E$4:$E$88) -> 200
... A40: 46274 | B40: Wtw Ccc Tccc 2026SEP | C40: WTW Health Premium (reimbursed by Via Benefits) | D40: Excluded | E40: 2576 | G40: Streaming – ESPN (Sept billed as Disney Plus) | H40: =SUMIF($C$4:$C$88,G40,$E$4:$E$88) -> 13.87
A41: 46275 | B41: NC Quick Pass 877-769-7277 NC | C41: Tolls & Parking | D41: Transportation | E41: 68.24 | G41: Total spending | H41: =SUM(H4:H40) -> 11515.63
A42: 46275 | B42: Aci*Blue Cross NC | C42: Health Insurance – Blue Cross NC | D42: Insurance | E42: 216.25
A43: 46275 | B43: Pt *Dosher Hospita | C43: Medical – Dosher Hospital (Southport) | D43: Health | E43: 100.28 | G43: Not counted as spending
A44: 46275 | B44: Bemc - Ecc WWW.Bemc.Coop NC | C44: Utility – Electric (BEMC) | D44: Utilities | E44: 419.66 | G44: Credit Card Payoff – American Express | H44: =SUMIF($C$4:$C$88,G44,$E$4:$E$88) -> 4738.51
A45: 46275 | B45: Focus Broadband Clover.Com NC | C45: Internet – Focus Broadband | D45: Phone & Internet | E45: 80.79 | G45: WTW Health Premium (reimbursed by Via Benefits) | H45: =SUMIF($C$4:$C$88,G45,$E$4:$E$88) -> 2576
A46: 46275 | B46: Lowe's #682 Southport NC | C46: Retail – Lowe's (home improvement) | D46: Retail | E46: 85.27
A47: 46279 | B47: Opc*Brunswick CO U | C47: Utility – Water/Sewer (Brunswick County) | D47: Utilities | E47: 81.31
A48: 46279 | B48: Opc Utl*Service Fe | C48: Utility – Water/Sewer (Brunswick County) | D48: Utilities | E48: 2.95
A49: 46279 | B49: Kiwanis Club of So Southport NC | C49: Donations & Clubs (Kiwanis) | D49: Other | E49: 200
A50: 46279 | B50: Disney Plus Ecom | C50: Streaming – ESPN (Sept billed as Disney Plus) | D50: Streaming | E50: 13.87
A51: 46279 | B51: Google Youtubetv N | C51: Streaming – YouTube TV (Google) | D51: Streaming | E51: 43.43
A52: 46279 | B52: Village Store 4 Wallace NC | C52: Gas & Convenience Stores | D52: Transportation | E52: 52.03
A53: 46279 | B53: NY Pizza - Bass PR Cary NC | C53: Restaurants & Takeout | D53: Food | E53: 34.89
A54: 46279 | B54: Lowes Food #235 Bolivia NC | C54: Grocery – Lowes Foods | D54: Groceries | E54: 88.63
A55: 46279 | B55: Dept Education Student Ln 0000 | C55: Student Loan (Dept of Education) | D55: Student Loan | E55: 160.37
A56: 46280 | B56: Amk Duke South Wps Durham | C56: Medical – Duke Hospital (Durham, food & parking) | D56: Health | E56: 8.75
A57: 46280 | B57: Autobks*Nextgen LA | C57: Yard Company (NextGen) | D57: Home | E57: 60
... A88: 46289 | B88: Moore Street Oyste | C88: Restaurants & Takeout | D88: Food | E88: 27.32
D89: Total spending | E89: =SUMIF(D4:D88,"<>Excluded",E4:E88) -> 11515.63
D90: Not counted (Excluded) | E90: =SUMIF(D4:D88,"Excluded",E4:E88) -> 7314.51

Sheet All Transactions
A1: All Checking Withdrawals – Wells Fargo Everyday Checking (…6004)
A2: Every debit on the four statements, 5/27/26 – 9/24/26. "Month" = statement period. Use the filter arrows to sort or filter.
A4: Month | B4: Date | C4: Description (from statement) | D4: Category | E4: Group | F4: Amount
A5: June 2026 | B5: 46169 | C5: Aci*Blue Cross NC Durham NC | D5: Health Insurance – Blue Cross NC | E5: Insurance | F5: 216.25
A6: June 2026 | B6: 46169 | C6: Chipotle 4232 Conway SC | D6: Restaurants & Takeout | E6: Food | F6: 24.53
A7: June 2026 | B7: 46170 | C7: Chick-Fil-A #04769 Shallotte NC | D7: Restaurants & Takeout | E7: Food | F7: 11.2
A8: June 2026 | B8: 46170 | C8: Dairy Queen #15351 Supply NC | D8: Restaurants & Takeout | E8: Food | F8: 7.35
A9: June 2026 | B9: 46170 | C9: Belk Syf Paymnt May 28 604583156390724 Dempseyleigh | D9: Retail – Belk (store card payments) | E9: Retail | F9: 386.69
A10: June 2026 | B10: 46171 | C10: Google *Youtube Tv | D10: Streaming – YouTube TV (Google) | E10: Streaming | F10: 89
A11: June 2026 | B11: 46171 | C11: Google *Youtube Tv | D11: Streaming – YouTube TV (Google) | E11: Streaming | F11: 11.78
A12: June 2026 | B12: 46171 | C12: Roku for Disney El | D12: Streaming – Disney (via Roku) | E12: Streaming | F12: 20.27
A13: June 2026 | B13: 46171 | C13: Lowes Food #235 Bolivia NC | D13: Grocery – Lowes Foods | E13: Groceries | F13: 125.08
A14: June 2026 | B14: 46174 | C14: Apple.Com/Bill 866-712-7753 | D14: Software & Online Subscriptions | E14: Subscriptions | F14: 13.8
A15: June 2026 | B15: 46174 | C15: DD *Doordash Bella | D15: Restaurants & Takeout | E15: Food | F15: 62.84
A16: June 2026 | B16: 46174 | C16: Ls Mad River 186-69321801 NC | D16: Retail – Local shops (Hippie Chick, Southport Spices, Mad River, Coastal Carolina) | E16: Retail | F16: 41.63
... A436: September 2026 | B436: 46289 | C436: Moore Street Oyste | D436: Restaurants & Takeout | E436: Food | F436: 27.32
E437: All withdrawals | F437: =SUM(F5:F436) -> 84517.24
